<?xml version="1.0" ?>
<!-- =================================================================================== -->
<!-- |    This document was autogenerated by xacro from urdf/ur10_robot.urdf.xacro     | -->
<!-- |    EDITING THIS FILE BY HAND IS NOT RECOMMENDED                                 | -->
<!-- =================================================================================== -->
<robot name="robot" xmlns:xacro="http://www.ros.org/wiki/xacro">
  <!-- ur10 -->
  <material name="gray">
    <color rgba="0.7 0.7 0.7 1" />
  </material>

  <!-- pole -->
  <link name="pole">
    <visual>
      <origin rpy="0 0 0" xyz="0 0 .355"/>
      <geometry>
				<!-- <mesh filename="cube.obj" scale=".1 .1 .355"/> -->
	 	    <box size=".15 .15 .71"/>
       </geometry>
       <material name="gray" />
    </visual>
    <collision>
      <origin rpy="0 0 0" xyz="0 0 0"/>
      <geometry>
	 	    <box size=".15 .15 .71"/>
      </geometry>
    </collision>
  </link>

  <joint name="world_joint" type="fixed">
    <parent link="pole"/>
    <child link="base_link"/>
    <origin rpy="0.0 0.0 0.0" xyz="0.0 0.0 0.71"/>
  </joint>

  <!-- arm -->
  <link name="base_link">
    <visual>
      <geometry>
        <mesh filename="ur_description/meshes/ur10/visual/Base.obj"/>
      </geometry>
      <material name="gray" />
    </visual>
    <collision>
      <geometry>
        <mesh filename="ur_description/meshes/ur10/collision/Base.obj"/>
      </geometry>
    </collision>
    <inertial>
      <mass value="4.0"/>
      <origin rpy="0 0 0" xyz="0.0 0.0 0.0"/>
      <inertia ixx="0.0061063308908" ixy="0.0" ixz="0.0" iyy="0.0061063308908" iyz="0.0" izz="0.01125"/>
    </inertial>
  </link>
  <joint name="shoulder_pan_joint" type="revolute">
    <parent link="base_link"/>
    <child link="shoulder_link"/>
    <origin rpy="0.0 0.0 0.0" xyz="0.0 0.0 0.1273"/>
    <axis xyz="0 0 1"/>
    <limit effort="330.0" lower="-6.2831853" upper="6.2831853" velocity="2.16"/>
    <dynamics damping="0.0" friction="0.0"/>
  </joint>
  <link name="shoulder_link">
    <visual>
      <geometry>
        <mesh filename="ur_description/meshes/ur10/visual/Shoulder.obj"/>
      </geometry>
      <material name="gray" />
    </visual>
    <collision>
      <geometry>
        <mesh filename="ur_description/meshes/ur10/collision/Shoulder.obj"/>
      </geometry>
    </collision>
    <inertial>
      <mass value="7.778"/>
      <origin rpy="0 0 0" xyz="0.0 0.0 0.0"/>
      <inertia ixx="0.0314743125769" ixy="0.0" ixz="0.0" iyy="0.0314743125769" iyz="0.0" izz="0.021875625"/>
    </inertial>
  </link>
  <joint name="shoulder_lift_joint" type="revolute">
    <parent link="shoulder_link"/>
    <child link="upper_arm_link"/>
    <origin rpy="0.0 0.0 0.0" xyz="0.0 0.220941 0.0"/>
    <axis xyz="0 1 0"/>
    <limit effort="330.0" lower="-6.2831853" upper="6.2831853" velocity="2.16"/>
    <dynamics damping="0.0" friction="0.0"/>
  </joint>
  <link name="upper_arm_link">
    <visual>
      <geometry>
        <mesh filename="ur_description/meshes/ur10/visual/UpperArm.obj"/>
      </geometry>
      <material name="gray"/>
    </visual>
    <collision>
      <geometry>
        <mesh filename="ur_description/meshes/ur10/collision/UpperArm.obj"/>
      </geometry>
    </collision>
    <inertial>
      <mass value="12.93"/>
      <origin rpy="0 0 0" xyz="0.0 0.0 0.306"/>
      <inertia ixx="0.421753803798" ixy="0.0" ixz="0.0" iyy="0.421753803798" iyz="0.0" izz="0.036365625"/>
    </inertial>
  </link>
  <joint name="elbow_joint" type="revolute">
    <parent link="upper_arm_link"/>
    <child link="forearm_link"/>
    <origin rpy="0.0 0.0 0.0" xyz="0.0 -0.1719 0.612"/>
    <axis xyz="0 1 0"/>
    <limit effort="150.0" lower="-6.2831853" upper="6.2831853" velocity="3.15"/>
    <dynamics damping="0.0" friction="0.0"/>
  </joint>
  <link name="forearm_link">
    <visual>
      <geometry>
        <mesh filename="ur_description/meshes/ur10/visual/Forearm.obj"/>
      </geometry>
      <material name="gray" />
    </visual>
    <collision>
      <geometry>
        <mesh filename="ur_description/meshes/ur10/collision/Forearm.obj"/>
      </geometry>
    </collision>
    <inertial>
      <mass value="3.87"/>
      <origin rpy="0 0 0" xyz="0.0 0.0 0.28615"/>
      <inertia ixx="0.111069694097" ixy="0.0" ixz="0.0" iyy="0.111069694097" iyz="0.0" izz="0.010884375"/>
    </inertial>
  </link>
  <joint name="wrist_1_joint" type="revolute">
    <parent link="forearm_link"/>
    <child link="wrist_1_link"/>
    <origin rpy="0.0 0.0 0.0" xyz="0.0 0.0 0.5723"/>
    <axis xyz="0 1 0"/>
    <limit effort="54.0" lower="-6.2831853" upper="6.2831853" velocity="3.2"/>
    <dynamics damping="0.0" friction="0.0"/>
  </joint>
  <link name="wrist_1_link">
    <visual>
      <geometry>
        <mesh filename="ur_description/meshes/ur10/visual/Wrist1.obj"/>
      </geometry>
      <material name="gray" />
    </visual>
    <collision>
      <geometry>
        <mesh filename="ur_description/meshes/ur10/collision/Wrist1.obj"/>
      </geometry>
    </collision>
    <inertial>
      <mass value="1.96"/>
      <origin rpy="0 0 0" xyz="0.0 0.0 0.0"/>
      <inertia ixx="0.0051082479567" ixy="0.0" ixz="0.0" iyy="0.0051082479567" iyz="0.0" izz="0.0055125"/>
    </inertial>
  </link>
  <joint name="wrist_2_joint" type="revolute">
    <parent link="wrist_1_link"/>
    <child link="wrist_2_link"/>
    <origin rpy="0.0 0.0 0.0" xyz="0.0 0.1149 0.0"/>
    <axis xyz="0 0 1"/>
    <limit effort="54.0" lower="-6.2831853" upper="6.2831853" velocity="3.2"/>
    <dynamics damping="0.0" friction="0.0"/>
  </joint>
  <link name="wrist_2_link">
    <visual>
      <geometry>
        <mesh filename="ur_description/meshes/ur10/visual/Wrist2.obj"/>
      </geometry>
      <material name="gray" />
    </visual>
    <collision>
      <geometry>
        <mesh filename="ur_description/meshes/ur10/collision/Wrist2.obj"/>
      </geometry>
    </collision>
    <inertial>
      <mass value="1.96"/>
      <origin rpy="0 0 0" xyz="0.0 0.0 0.0"/>
      <inertia ixx="0.0051082479567" ixy="0.0" ixz="0.0" iyy="0.0051082479567" iyz="0.0" izz="0.0055125"/>
    </inertial>
  </link>
  <joint name="wrist_3_joint" type="revolute">
    <parent link="wrist_2_link"/>
    <child link="wrist_3_link"/>
    <origin rpy="0.0 0.0 0.0" xyz="0.0 0.0 0.1157"/>
    <axis xyz="0 1 0"/>
    <limit effort="54.0" lower="-6.2831853" upper="6.2831853" velocity="3.2"/>
    <dynamics damping="0.0" friction="0.0"/>
  </joint>
  <link name="wrist_3_link">
    <visual>
      <geometry>
        <mesh filename="ur_description/meshes/ur10/visual/Wrist3.obj"/>
      </geometry>
      <material name="gray" />
    </visual>
    <collision>
      <geometry>
        <mesh filename="ur_description/meshes/ur10/collision/Wrist3.obj"/>
      </geometry>
    </collision>
    <inertial>
      <mass value="0.202"/>
      <origin rpy="0 0 0" xyz="0.0 0.0 0.0"/>
      <inertia ixx="0.000526462289415" ixy="0.0" ixz="0.0" iyy="0.000526462289415" iyz="0.0" izz="0.000568125"/>
    </inertial>
  </link>
  <transmission name="shoulder_pan_trans">
    <type>transmission_interface/SimpleTransmission</type>
    <joint name="shoulder_pan_joint"/>
    <actuator name="shoulder_pan_motor">
      <hardwareInterface>EffortJointInterface</hardwareInterface>
      <mechanicalReduction>1</mechanicalReduction>
    </actuator>
  </transmission>
  <transmission name="shoulder_lift_trans">
    <type>transmission_interface/SimpleTransmission</type>
    <joint name="shoulder_lift_joint"/>
    <actuator name="shoulder_lift_motor">
      <hardwareInterface>EffortJointInterface</hardwareInterface>
      <mechanicalReduction>1</mechanicalReduction>
    </actuator>
  </transmission>
  <transmission name="elbow_trans">
    <type>transmission_interface/SimpleTransmission</type>
    <joint name="elbow_joint"/>
    <actuator name="elbow_motor">
      <hardwareInterface>EffortJointInterface</hardwareInterface>
      <mechanicalReduction>1</mechanicalReduction>
    </actuator>
  </transmission>
  <transmission name="wrist_1_trans">
    <type>transmission_interface/SimpleTransmission</type>
    <joint name="wrist_1_joint"/>
    <actuator name="wrist_1_motor">
      <hardwareInterface>EffortJointInterface</hardwareInterface>
      <mechanicalReduction>1</mechanicalReduction>
    </actuator>
  </transmission>
  <transmission name="wrist_2_trans">
    <type>transmission_interface/SimpleTransmission</type>
    <joint name="wrist_2_joint"/>
    <actuator name="wrist_2_motor">
      <hardwareInterface>EffortJointInterface</hardwareInterface>
      <mechanicalReduction>1</mechanicalReduction>
    </actuator>
  </transmission>
  <transmission name="wrist_3_trans">
    <type>transmission_interface/SimpleTransmission</type>
    <joint name="wrist_3_joint"/>
    <actuator name="wrist_3_motor">
      <hardwareInterface>EffortJointInterface</hardwareInterface>
      <mechanicalReduction>1</mechanicalReduction>
    </actuator>
  </transmission>

  <joint name="attachement_joint" type="fixed">
    <parent link="wrist_3_link"/>
    <child link="rh_p12_rn_base"/>
    <origin rpy="-1.57079632 0 0" xyz="0 .09 0"/><!--.082515-->
  </joint>

  <!-- rh p12 rn a -->
  <!-- End Effector -->
  <!-- base -->
  <link name="rh_p12_rn_base">
    <collision>
      <origin rpy="0 0 0" xyz="0 0 0"/>
      <geometry>
        <mesh filename="package://rh_p12_rn_description/meshes/base.stl" scale="0.001 0.001 0.001"/>
      </geometry>
    </collision>
    <visual>
      <origin rpy="0 0 0" xyz="0 0 0"/>
      <geometry>
        <mesh filename="package://rh_p12_rn_description/meshes/base.stl" scale="0.001 0.001 0.001"/>
      </geometry>
      <material name="grey"/>
    </visual>
    <inertial>
      <origin rpy="0 0 0" xyz="0.000 0.000 0.032"/>
      <mass value="0.236"/>
      <!--<inertia ixx="0.00017" ixy="0.0" ixz="0.0" iyy="0.00011" iyz="0.0" izz="0.00017" />-->
      <inertia ixx="1.0" ixy="0.0" ixz="0.0" iyy="1.0" iyz="0.0" izz="1.0"/>
    </inertial>
  </link>
  <!-- Joint -->
  <joint name="rh_r1" type="revolute">
    <parent link="rh_p12_rn_base"/>
    <child link="rh_p12_rn_r1"/>
    <origin rpy="0 0 0" xyz="0.0 0.008 0.048"/>
    <axis xyz="1 0 0"/>
    <limit effort="100" lower="0.0" upper="1.2" velocity="1000"/>
    <!-- <dynamics damping="0.7"/> -->
  </joint>
  <transmission name="tran_r1">
    <type>transmission_interface/SimpleTransmission</type>
    <joint name="rh_r1"> 
      <hardwareInterface>hardware_interface/EffortJointInterface</hardwareInterface>
    </joint>
    <actuator name="motor_r1">
      <hardwareInterface>hardware_interface/EffortJointInterface</hardwareInterface>
      <mechanicalReduction>1</mechanicalReduction>
    </actuator>
  </transmission>
  <!-- rh_p12_rn_r1 -->
  <link name="rh_p12_rn_r1">
    <collision>
      <origin rpy="0 0 0" xyz="0 0 0"/>
      <geometry>
        <mesh filename="package://rh_p12_rn_description/meshes/r1.stl" scale="0.001 0.001 0.001"/>
      </geometry>
    </collision>
    <visual>
      <origin rpy="0 0 0" xyz="0 0 0"/>
      <geometry>
        <mesh filename="package://rh_p12_rn_description/meshes/r1.stl" scale="0.001 0.001 0.001"/>
      </geometry>
      <material name="grey"/>
    </visual>
    <inertial>
      <origin rpy="0 0 0" xyz="0.000 0.034 0.004"/>
      <mass value="0.068"/>
      <!--<inertia ixx="0.00004" ixy="0.0" ixz="0.0" iyy="0.00002" iyz="-0.00001" izz="0.00002" />-->
      <inertia ixx="1.0" ixy="0.0" ixz="0.0" iyy="1.0" iyz="0.0" izz="1.0"/>
    </inertial>
  </link>
  <!-- Right Joint 2 -->
  <joint name="rh_r2" type="revolute">
    <parent link="rh_p12_rn_r1"/>
    <child link="rh_p12_rn_r2"/>
    <origin rpy="0.0 0 0" xyz="0.0 0.0493634 0.0285"/>
    <!-- <origin rpy="0 0 0" xyz="0.0 0.0493634 0.0285"/> -->
    <axis xyz="-1 0 0"/>
    <limit effort="100" lower="0.0" upper="1.2" velocity="1000"/>
    <!-- <dynamics damping="0.7"/> -->
  </joint>
  <transmission name="tran_r2">
    <type>transmission_interface/SimpleTransmission</type>
    <joint name="rh_r2">
      <hardwareInterface>hardware_interface/EffortJointInterface</hardwareInterface>
    </joint>
    <actuator name="motor_r2">
      <hardwareInterface>hardware_interface/EffortJointInterface</hardwareInterface>
      <mechanicalReduction>1</mechanicalReduction>
    </actuator>
  </transmission>
  <!-- rh_p12_rn_r2 -->
  <link name="rh_p12_rn_r2">
    <collision>
      <origin rpy="0 0 0" xyz="0 0 0"/>
      <geometry>
        <mesh filename="package://rh_p12_rn_description/meshes/r2.stl" scale="0.001 0.001 0.001"/>
      </geometry>
    </collision>
    <visual>
      <origin rpy="0 0 0" xyz="0 0 0"/>
      <geometry>
        <mesh filename="package://rh_p12_rn_description/meshes/r2.stl" scale="0.001 0.001 0.001"/>
      </geometry>
      <material name="grey"/>
    </visual>
    <inertial>
      <origin rpy="0 0 0" xyz="0.000 0.006 0.011"/>
      <mass value="0.022"/>
      <!--<inertia ixx="0.0" ixy="0.0" ixz="0.0" iyy="0.00001" iyz="0.0" izz="0.0" />-->
      <inertia ixx="1.0" ixy="0.0" ixz="0.0" iyy="1.0" iyz="0.0" izz="1.0"/>
    </inertial>
  </link>
  <!-- Left Joint 1 -->
  <joint name="rh_l1" type="revolute">
    <parent link="rh_p12_rn_base"/>
    <child link="rh_p12_rn_l1"/>
    <origin rpy="0 0 0" xyz="0.0 -0.008 0.048"/>
    <axis xyz="-1 0 0"/>
    <limit effort="100" lower="0.0" upper="1.2" velocity="1000"/>
    <!-- <dynamics damping="0.7"/> -->
  </joint>
  <transmission name="tran_l1">
    <type>transmission_interface/SimpleTransmission</type>
    <joint name="rh_l1">
      <hardwareInterface>hardware_interface/EffortJointInterface</hardwareInterface>
    </joint>
    <actuator name="motor_l1">
      <hardwareInterface>hardware_interface/EffortJointInterface</hardwareInterface>
      <mechanicalReduction>1</mechanicalReduction>
    </actuator>
  </transmission>
  <!-- rh_p12_rn_l1 -->
  <link name="rh_p12_rn_l1">
    <collision>
      <origin rpy="0 0 0" xyz="0 0 0"/>
      <geometry>
        <mesh filename="package://rh_p12_rn_description/meshes/l1.stl" scale="0.001 0.001 0.001"/>
      </geometry>
    </collision>
    <visual>
      <origin rpy="0 0 0" xyz="0 0 0"/>
      <geometry>
        <mesh filename="package://rh_p12_rn_description/meshes/l1.stl" scale="0.001 0.001 0.001"/>
      </geometry>
      <material name="grey"/>
    </visual>
    <inertial>
      <origin rpy="0 0 0" xyz="0.000 -0.034 0.004"/>
      <mass value="0.068"/>
      <!--<inertia ixx="0.00004" ixy="0.0" ixz="0.0" iyy="0.00002" iyz="0.00001" izz="0.00002" />-->
      <inertia ixx="1.0" ixy="0.0" ixz="0.0" iyy="1.0" iyz="0.0" izz="1.0"/>
    </inertial>
  </link>
  <!-- Left Joint 2 -->
  <joint name="rh_l2" type="revolute">
    <parent link="rh_p12_rn_l1"/>
    <child link="rh_p12_rn_l2"/>
    <origin rpy="0.0 0 0" xyz="0.0 -0.0493634 0.0285"/>
    <!-- <origin rpy="0 0 0" xyz="0.0 -0.0493634 0.0285"/> -->
    <axis xyz="1 0 0"/>
    <limit effort="100" lower="0.0" upper="1.2" velocity="1000"/>
    <!-- <dynamics damping="0.7"/> -->
  </joint>
  <transmission name="tran_l2">
    <type>transmission_interface/SimpleTransmission</type>
    <joint name="rh_l2">
      <hardwareInterface>hardware_interface/EffortJointInterface</hardwareInterface>
    </joint>
    <actuator name="motor_l2">
      <hardwareInterface>hardware_interface/EffortJointInterface</hardwareInterface>
      <mechanicalReduction>1</mechanicalReduction>
    </actuator>
  </transmission>
  <!-- rh_p12_rn_l2 -->
  <link name="rh_p12_rn_l2">
    <collision>
      <origin rpy="0 0 0" xyz="0 0 0"/>
      <geometry>
        <mesh filename="package://rh_p12_rn_description/meshes/l2.stl" scale="0.001 0.001 0.001"/>
      </geometry>
    </collision>
    <visual>
      <origin rpy="0 0 0" xyz="0 0 0"/>
      <geometry>
        <mesh filename="package://rh_p12_rn_description/meshes/l2.stl" scale="0.001 0.001 0.001"/>
      </geometry>
      <material name="grey"/>
    </visual>
    <inertial>
      <origin rpy="0 0 0" xyz="0.000 -0.006 0.011"/>
      <mass value="0.022"/>
      <!--<inertia ixx="0.0" ixy="0.0" ixz="0.0" iyy="0.00001" iyz="0.0" izz="0.0" />-->
      <inertia ixx="1.0" ixy="0.0" ixz="0.0" iyy="1.0" iyz="0.0" izz="1.0"/>
    </inertial>
  </link>
</robot>

